Workbook

Sheet Stars
A1: star_name | B1: has_planets | C1: planet_count | D1: planet_count_override | E1: confirmed_exoplanet_count | F1: distance_ly | G1: planet_names | H1: notes | I1: hyg_id | J1: nasa_hosts | K1: match_method | L1: controversial_planet_count | M1: distance_pc | N1: spectral_type | O1: hyg_luminosity_solar | P1: apparent_magnitude | Q1: hip | R1: hd | S1: hr | T1: gliese | U1: bayer_flamsteed | V1: proper_name | W1: ra_deg_j2000 | X1: dec_deg_j2000 | Y1: x_ly | Z1: y_ly | AA1: z_ly | AB1: component | AC1: primary_hyg_id | AD1: archive_planet_count | AE1: solar_system_planet_count | AF1: x_pc | AG1: y_pc | AH1: z_pc | AI1: system_id | AJ1: faction_owners
A2: Sol | B2: =IF(C2>0,"Yes",IF(D2="","Unknown","No")) | C2: =IF(D2="",E2+8,D2) | E2: =COUNTIFS(Planets!$C:$C,I2,Planets!$E:$E,1) | F2: 0 | G2: Mercury; Venus; Earth; Mars; Jupiter; Saturn; Uranus; Neptune | H2: Sol: 8 Solar System planets; outside NASA exoplanet export. | I2: 0 | L2: 0 | M2: 0 | N2: G2V | O2: 1 | P2: -26.7 | V2: Sol | W2: 0 | X2: 0 | Y2: 0 | Z2: 0 | AA2: 0 | AB2: 1 | AC2: 0 | AD2: 0 | AE2: 8 | AF2: 0 | AG2: 0 | AH2: 0 | AI2: hyg:0
A3: Proxima Centauri | B3: =IF(C3>0,"Yes",IF(D3="","Unknown","No")) | C3: =IF(D3="",E3+0,D3) | E3: =COUNTIFS(Planets!$C:$C,I3,Planets!$E:$E,1) | F3: 4.2266605 | G3: Proxima Cen b; Proxima Cen d | I3: 70666 | J3: Proxima Cen | K3: verified alias | L3: 0 | M3: 1.2959 | N3: M5Ve | O3: 5.7703214e-05 | P3: 11.01 | Q3: 70890 | T3: Gl 551 | V3: Proxima Centauri | W3: 217.43977 | X3: -62.679485 | Y3: -1.5403192 | Z3: -1.1788955 | AA3: -3.7547742 | AB3: 1 | AC3: 70666 | AD3: 2 | AE3: 0 | AF3: -0.472264 | AG3: -0.361451 | AH3: -1.151219 | AI3: hyg:70666
A4: Toliman | B4: =IF(C4>0,"Yes",IF(D4="","Unknown","No")) | C4: =IF(D4="",E4+0,D4) | E4: =COUNTIFS(Planets!$C:$C,I4,Planets!$E:$E,1) | F4: 4.3209197 | I4: 71453 | L4: 0 | M4: 1.3248 | N4: K1V | O4: 0.44096082 | P4: 1.35 | Q4: 71681 | R4: 128621 | S4: 5460 | T4: Gl 559B | U4: Alp2Cen | V4: Toliman | W4: 219.90519 | X4: -60.8383 | Y4: -1.6150644 | Z4: -1.3501993 | AA4: -3.772566 | AB4: 2 | AC4: 71456 | AD4: 0 | AE4: 0 | AF4: -0.495181 | AG4: -0.413973 | AH4: -1.156674 | AI4: hyg:71456
A5: Rigil Kentaurus | B5: =IF(C5>0,"Yes",IF(D5="","Unknown","No")) | C5: =IF(D5="",E5+0,D5) | E5: =COUNTIFS(Planets!$C:$C,I5,Planets!$E:$E,1) | F5: 4.3209197 | I5: 71456 | L5: 0 | M5: 1.3248 | N5: G2V | O5: 1.5431211 | P5: -0.01 | Q5: 71683 | R5: 128620 | S5: 5459 | T5: Gl 559A | U5: Alp1Cen | V5: Rigil Kentaurus | W5: 219.91147 | X5: -60.833976 | Y5: -1.6151362 | Z5: -1.3505614 | AA5: -3.7724062 | AB5: 1 | AC5: 71456 | AD5: 0 | AE5: 0 | AF5: -0.495203 | AG5: -0.414084 | AH5: -1.156625 | AI5: hyg:71456
A6: Barnard's Star | B6: =IF(C6>0,"Yes",IF(D6="","Unknown","No")) | C6: =IF(D6="",E6+0,D6) | E6: =COUNTIFS(Planets!$C:$C,I6,Planets!$E:$E,1) | F6: 5.94844 | G6: Barnard b; Barnard c; Barnard d; Barnard e | I6: 87665 | J6: Barnard's star | K6: catalog identifier | L6: 0 | M6: 1.8238 | N6: sdM4 | O6: 0.00044258837 | P6: 9.54 | Q6: 87937 | T6: Gl 699 | V6: Barnard's Star | W6: 269.45208 | X6: 4.693388 | Y6: -0.056663148 | Z6: -5.9249992 | AA6: 0.48637418 | AB6: 1 | AC6: 87665 | AD6: 4 | AE6: 0 | AF6: -0.017373 | AG6: -1.816613 | AH6: 0.149123 | AI6: hyg:87665
A7: Wolf 359 | B7: =IF(C7>0,"Yes",IF(D7="","Unknown","No")) | C7: =IF(D7="",E7+0,D7) | E7: =COUNTIFS(Planets!$C:$C,I7,Planets!$E:$E,1) | F7: 7.7970944 | I7: 118720 | L7: 0 | M7: 2.3906 | N7: M6 | O7: 2.0758693e-05 | P7: 13.45 | T7: Gl 406 | V7: Wolf 359 | W7: 164.12226 | X7: 7.01532 | Y7: -7.4455337 | Z7: 2.1178443 | AA7: 0.95256253 | AB7: 1 | AC7: 118720 | AD7: 0 | AE7: 0 | AF7: -2.282811 | AG7: 0.649334 | AH7: 0.292057 | AI7: hyg:118720
A8: Lalande 21185 | B8: =IF(C8>0,"Yes",IF(D8="","Unknown","No")) | C8: =IF(D8="",E8+0,D8) | E8: =COUNTIFS(Planets!$C:$C,I8,Planets!$E:$E,1) | F8: 8.3068768 | G8: GJ 411 b; HD 95735 c | H8: GJ 411: Catalog distances differ by >20%; HYG controls selection. | I8: 53879 | J8: GJ 411 | K8: catalog identifier | L8: 0 | M8: 2.5469 | N8: M2V | O8: 0.0057016427 | P8: 7.49 | Q8: 54035 | R8: 95735 | T8: Gl 411 | V8: Lalande 21185 | W8: 165.83448 | X8: 35.969877 | Y8: -6.5166044 | Z8: 1.6448229 | AA8: 4.8776817 | AB8: 1 | AC8: 53879 | AD8: 2 | AE8: 0 | AF8: -1.998 | AG8: 0.504305 | AH8: 1.495504 | AI8: hyg:53879
A9: Gl 65A | B9: =IF(C9>0,"Yes",IF(D9="","Unknown","No")) | C9: =IF(D9="",E9+0,D9) | E9: =COUNTIFS(Planets!$C:$C,I9,Planets!$E:$E,1) | F9: 8.5671496 | I9: 118079 | L9: 0 | M9: 2.6267 | N9: dM5.5e | O9: 5.6337815e-05 | P9: 12.57 | T9: Gl 65A | W9: 24.752985 | X9: -17.949782 | Y9: 7.4053773 | Z9: 3.4147594 | AA9: -2.641746 | AB9: 1 | AC9: 118079 | AD9: 0 | AE9: 0 | AF9: 2.270499 | AG9: 1.04697 | AH9: -0.809963 | AI9: hyg:118079
A10: Gl 65B | B10: =IF(C10>0,"Yes",IF(D10="","Unknown","No")) | C10: =IF(D10="",E10+0,D10) | E10: =COUNTIFS(Planets!$C:$C,I10,Planets!$E:$E,1) | F10: 8.5671496 | I10: 118080 | L10: 0 | M10: 2.6267 | N10: dM5.5e | O10: 4.9980431e-05 | P10: 12.7 | T10: Gl 65B | W10: 24.752985 | X10: -17.949782 | Y10: 7.4058078 | Z10: 3.4149584 | AA10: -2.6418993 | AB10: 2 | AC10: 118079 | AD10: 0 | AE10: 0 | AF10: 2.270631 | AG10: 1.047031 | AH10: -0.81001 | AI10: hyg:118079
A11: Sirius | B11: =IF(C11>0,"Yes",IF(D11="","Unknown","No")) | C11: =IF(D11="",E11+0,D11) | E11: =COUNTIFS(Planets!$C:$C,I11,Planets!$E:$E,1) | F11: 8.6010698 | I11: 32263 | L11: 0 | M11: 2.6371 | N11: A0m... | O11: 22.824433 | P11: -1.44 | Q11: 32349 | R11: 48915 | S11: 2491 | T11: Gl 244A | U11: 9Alp CMa | V11: Sirius | W11: 101.28722 | X11: -16.716116 | Y11: -1.612266 | Z11: 8.0780161 | AA11: -2.4738472 | AB11: 1 | AC11: 32263 | AD11: 0 | AE11: 0 | AF11: -0.494323 | AG11: 2.476731 | AH11: -0.758485 | AI11: hyg:32263
A12: Gl 244B | B12: =IF(C12>0,"Yes",IF(D12="","Unknown","No")) | C12: =IF(D12="",E12+0,D12) | E12: =COUNTIFS(Planets!$C:$C,I12,Planets!$E:$E,1) | F12: 8.6010698 | I12: 118441 | L12: 0 | M12: 2.6371 | N12: DA2 | O12: 0.0025491771 | P12: 8.44 | T12: Gl 244B | W12: 101.28839 | X12: -16.71524 | Y12: -1.6124486 | Z12: 8.0782868 | AA12: -2.4737983 | AB12: 2 | AC12: 32263 | AD12: 0 | AE12: 0 | AF12: -0.494379 | AG12: 2.476814 | AH12: -0.75847 | AI12: hyg:32263
A13: Ross 154 | B13: =IF(C13>0,"Yes",IF(D13="","Unknown","No")) | C13: =IF(D13="",E13+0,D13) | E13: =COUNTIFS(Planets!$C:$C,I13,Planets!$E:$E,1) | F13: 9.6861921 | I13: 92115 | L13: 0 | M13: 2.9698 | N13: M3.5Ve | O13: 0.00054651237 | P13: 10.37 | Q13: 92403 | T13: Gl 729 | V13: Ross 154 | W13: 282.45553 | X13: -23.836232 | Y13: 1.9108948 | Z13: -8.6511479 | AA13: -3.9142777 | AB13: 1 | AC13: 92115 | AD13: 0 | AE13: 0 | AF13: 0.585883 | AG13: -2.652454 | AH13: -1.200123 | AI13: hyg:92115
A14: Ross 248 | B14: =IF(C14>0,"Yes",IF(D14="","Unknown","No")) | C14: =IF(D14="",E14+0,D14) | E14: =COUNTIFS(Planets!$C:$C,I14,Planets!$E:$E,1) | F14: 10.334591 | I14: 119585 | L14: 0 | M14: 3.1686 | N14: dM6 e | O14: 0.00010607181 | P14: 12.29 | T14: Gl 905 | V14: Ross 248 | W14: 355.47568 | X14: 44.174924 | Y14: 7.379774 | Z14: -0.58389167 | AA14: 7.1926418 | AB14: 1 | AC14: 119585 | AD14: 0 | AE14: 0 | AF14: 2.262649 | AG14: -0.179022 | AH14: 2.205274 | AI14: hyg:119585
A15: Ran | B15: =IF(C15>0,"Yes",IF(D15="","Unknown","No")) | C15: =IF(D15="",E15+0,D15) | E15: =COUNTIFS(Planets!$C:$C,I15,Planets!$E:$E,1) | F15: 10.489515 | G15: eps Eri b | I15: 16496 | J15: eps Eri | K15: catalog identifier | L15: 0 | M15: 3.2161 | N15: K2V | O15: 0.29295438 | P15: 3.72 | Q15: 16537 | R15: 22049 | S15: 1084 | T15: Gl 144 | U15: 18Eps Eri | V15: Ran | W15: 53.23272 | X15: -9.458262 | Y15: 6.1936118 | Z15: 8.289023 | AA15: -1.7238115 | AB15: 1 | AC15: 16496 | AD15: 1 | AE15: 0 | AF15: 1.89897 | AG15: 2.541426 | AH15: -0.528523 | AI15: hyg:16496
A16: Lacaille 9352 | B16: =IF(C16>0,"Yes",IF(D16="","Unknown","No")) | C16: =IF(D16="",E16+0,D16) | E16: =COUNTIFS(Planets!$C:$C,I16,Planets!$E:$E,1) | F16: 10.684557 | G16: GJ 887 b; GJ 887 c; GJ 887 d; GJ 887 e | I16: 113687 | J16: GJ 887 | K16: catalog identifier | L16: 0 | M16: 3.2759 | N16: M2/M3V | O16: 0.010734949 | P16: 7.35 | Q16: 114046 | R16: 217987 | T16: Gl 887 | V16: Lacaille 9352 | W16: 346.46296 | X16: -35.853073 | Y16: 8.4198313 | Z16: -2.0265824 | AA16: -6.2582005 | AB16: 1 | AC16: 113687 | AD16: 4 | AE16: 0 | AF16: 2.581532 | AG16: -0.621353 | AH16: -1.918773 | AI16: hyg:113687
A17: Ross 128 | B17: =IF(C17>0,"Yes",IF(D17="","Unknown","No")) | C17: =IF(D17="",E17+0,D17) | E17: =COUNTIFS(Planets!$C:$C,I17,Planets!$E:$E,1) | F17: 10.943525 | G17: Ross 128 b | I17: 57375 | J17: Ross 128 | K17: catalog identifier | L17: 0 | M17: 3.3553 | N17: M4.5V | O17: 0.000349623 | P17: 11.12 | Q17: 57548 | T17: Gl 447 | V17: Ross 128 | W17: 176.93499 | X17: 0.804563 | Y17: -10.925886 | Z17: 0.58503322 | AA17: 0.15365553 | AB17: 1 | AC17: 57375 | AD17: 1 | AE17: 0 | AF17: -3.349892 | AG17: 0.179372 | AH17: 0.047111 | AI17: hyg:57375
A18: EZ Aqr | B18: =IF(C18>0,"Yes",IF(D18="","Unknown","No")) | C18: =IF(D18="",E18+0,D18) | E18: =COUNTIFS(Planets!$C:$C,I18,Planets!$E:$E,1) | F18: 11.082468 | I18: 119518 | L18: 0 | M18: 3.3979 | N18: M5 e | O18: 8.6776074e-05 | P18: 12.66 | T18: Gl 866A | V18: EZ Aqr | W18: 339.63843 | X18: -15.302542 | Y18: 10.012652 | Z18: -3.7157822 | AA18: -2.9221948 | AB18: 1 | AC18: 119518 | AD18: 0 | AE18: 0 | AF18: 3.069893 | AG18: -1.139264 | AH18: -0.895949 | AI18: hyg:119518
A19: Struve 2398 B | B19: =IF(C19>0,"Yes",IF(D19="","Unknown","No")) | C19: =IF(D19="",E19+0,D19) | E19: =COUNTIFS(Planets!$C:$C,I19,Planets!$E:$E,1) | F19: 11.267072 | G19: Gl 725 B c | H19: Gl 725 B: Catalog distances differ by >20%; HYG controls selection. | I19: 91487 | J19: Gl 725 B | K19: catalog identifier | L19: 0 | M19: 3.4545 | N19: K5 | O19: 0.0013702506 | P19: 9.7 | Q19: 91772 | R19: 173740 | T19: Gl 725B | V19: Struve 2398 B | W19: 280.69873 | X19: 59.626847 | Y19: 1.0572913 | Z19: -5.5980111 | AA19: 9.7207027 | AB19: 2 | AC19: 91484 | AD19: 1 | AE19: 0 | AF19: 0.324167 | AG19: -1.716358 | AH19: 2.980381 | AI19: hyg:91484
A20: Gl 820A | B20: =IF(C20>0,"Yes",IF(D20="","Unknown","No")) | C20: =IF(D20="",E20+0,D20) | E20: =COUNTIFS(Planets!$C:$C,I20,Planets!$E:$E,1) | F20: 11.371442 | I20: 103879 | L20: 0 | M20: 3.4865 | N20: K5V | O20: 0.088064323 | P20: 5.2 | Q20: 104214 | R20: 201091 | S20: 8085 | T20: Gl 820A | U20: 61 Cyg | W20: 316.72191 | X20: 38.749415 | Y20: 6.4557958 | Z20: -6.0783677 | AA20: 7.1163799 | AB20: 1 | AC20: 103879 | AD20: 0 | AE20: 0 | AF20: 1.979356 | AG20: -1.863636 | AH20: 2.181892 | AI20: hyg:103879
A21: Gl 280B | B21: =IF(C21>0,"Yes",IF(D21="","Unknown","No")) | C21: =IF(D21="",E21+0,D21) | E21: =COUNTIFS(Planets!$C:$C,I21,Planets!$E:$E,1) | F21: 11.406993 | I21: 118493 | L21: 0 | M21: 3.4974 | N21: DA | O21: 0.00055924228 | P21: 10.7 | T21: Gl 280B | W21: 114.82509 | X21: 5.226824 | Y21: -4.7692999 | Z21: 10.309872 | AA21: 1.0391668 | AB21: 2 | AC21: 37173 | AD21: 0 | AE21: 0 | AF21: -1.462274 | AG21: 3.161021 | AH21: 0.31861 | AI21: hyg:37173
A22: Gl 820B | B22: =IF(C22>0,"Yes",IF(D22="","Unknown","No")) | C22: =IF(D22="",E22+0,D22) | E22: =COUNTIFS(Planets!$C:$C,I22,Planets!$E:$E,1) | F22: 11.40895 | I22: 103883 | L22: 0 | M22: 3.498 | N22: K7V | O22: 0.040513522 | P22: 6.05 | Q22: 104217 | R22: 201092 | S22: 8086 | T22: Gl 820B | U22: 61 Cyg | W22: 316.72744 | X22: 38.742055 | Y22: 6.4783561 | Z22: -6.0984361 | AA22: 7.1387216 | AB22: 2 | AC22: 103879 | AD22: 0 | AE22: 0 | AF22: 1.986273 | AG22: -1.869789 | AH22: 2.188742 | AI22: hyg:103879
A23: Procyon | B23: =IF(C23>0,"Yes",IF(D23="","Unknown","No")) | C23: =IF(D23="",E23+0,D23) | E23: =COUNTIFS(Planets!$C:$C,I23,Planets!$E:$E,1) | F23: 11.461787 | I23: 37173 | L23: 0 | M23: 3.5142 | N23: F5IV-V | O23: 7.4404637 | P23: 0.4 | Q23: 37279 | R23: 61421 | S23: 2943 | T23: Gl 280A | U23: 10Alp CMi | V23: Procyon | W23: 114.8255 | X23: 5.224993 | Y23: -4.7922548 | Z23: 10.359281 | AA23: 1.0437787 | AB23: 1 | AC23: 37173 | AD23: 0 | AE23: 0 | AF23: -1.469312 | AG23: 3.17617 | AH23: 0.320024 | AI23: hyg:37173
A24: Gl 15B | B24: =IF(C24>0,"Yes",IF(D24="","Unknown","No")) | C24: =IF(D24="",E24+0,D24) | E24: =COUNTIFS(Planets!$C:$C,I24,Planets!$E:$E,1) | F24: 11.63726 | I24: 117979 | L24: 0 | M24: 3.568 | N24: M6 Ve | O24: 0.00041763799 | P24: 11.06 | T24: Gl 15B | W24: 4.5774 | X24: 44.023502 | Y24: 8.3423104 | Z24: 0.67018612 | AA24: 8.0886586 | AB24: 2 | AC24: 1472 | AD24: 0 | AE24: 0 | AF24: 2.557764 | AG24: 0.20548 | AH24: 2.479994 | AI24: hyg:1472
A25: Struve 2398 A | B25: =IF(C25>0,"Yes",IF(D25="","Unknown","No")) | C25: =IF(D25="",E25+0,D25) | E25: =COUNTIFS(Planets!$C:$C,I25,Planets!$E:$E,1) | F25: 11.640847 | G25: Gl 725 A b | I25: 91484 | J25: Gl 725 A | K25: catalog identifier | L25: 0 | M25: 3.5691 | N25: K5 | O25: 0.0029457779 | P25: 8.94 | Q25: 91768 | R25: 173739 | T25: Gl 725A | V25: Struve 2398 A | W25: 280.69768 | X25: 59.630396 | Y25: 1.0921542 | Z25: -5.783095 | AA25: 10.043493 | AB25: 1 | AC25: 91484 | AD25: 1 | AE25: 0 | AF25: 0.334856 | AG25: -1.773105 | AH25: 3.079349 | AI25: hyg:91484
A26: Groombridge 34 | B26: =IF(C26>0,"Yes",IF(D26="","Unknown","No")) | C26: =IF(D26="",E26+0,D26) | E26: =COUNTIFS(Planets!$C:$C,I26,Planets!$E:$E,1) | F26: 11.700208 | G26: GJ 15 A b; GJ 15 A c | I26: 1472 | J26: GJ 15 A | K26: catalog identifier | L26: 1 | M26: 3.5873 | N26: M1V | O26: 0.006510285 | P26: 8.09 | Q26: 1475 | R26: 1326 | T26: Gl 15A | V26: Groombridge 34 | W26: 4.59261 | X26: 44.022954 | Y26: 8.3863774 | Z26: 0.67406739 | AA26: 8.1312644 | AB26: 1 | AC26: 1472 | AD26: 2 | AE26: 0 | AF26: 2.571275 | AG26: 0.20667 | AH26: 2.493057 | AI26: hyg:1472
A27: Gl 845 | B27: =IF(C27>0,"Yes",IF(D27="","Unknown","No")) | C27: =IF(D27="",E27+0,D27) | E27: =COUNTIFS(Planets!$C:$C,I27,Planets!$E:$E,1) | F27: 11.814689 | G27: eps Ind A b | I27: 108526 | J27: eps Ind A | K27: verified alias | L27: 0 | M27: 3.6224 | N27: K5V | O27: 0.15205475 | P27: 4.69 | Q27: 108870 | R27: 209100 | S27: 8387 | T27: Gl 845 | U27: Eps Ind | W27: 330.83229 | X27: -56.785977 | Y27: 5.6509495 | Z27: -3.1530026 | AA27: -9.8835395 | AB27: 1 | AC27: 108526 | AD27: 1 | AE27: 0 | AF27: 1.732589 | AG27: -0.966715 | AH27: -3.030307 | AI27: hyg:108526
A28: GJ 1111 | B28: =IF(C28>0,"Yes",IF(D28="","Unknown","No")) | C28: =IF(D28="",E28+0,D28) | E28: =COUNTIFS(Planets!$C:$C,I28,Planets!$E:$E,1) | F28: 11.825778 | I28: 118541 | L28: 0 | M28: 3.6258 | N28: M6.5 | O28: 1.3639549e-05 | P28: 14.81 | T28: GJ 1111 | W28: 127.45866 | X28: 26.778532 | Y28: -6.4202317 | Z28: 8.3801022 | AA28: 5.327647 | AB28: 1 | AC28: 118541 | AD28: 0 | AE28: 0 | AF28: -1.968452 | AG28: 2.569351 | AH28: 1.633464 | AI28: hyg:118541
A29: Gl 71 | B29: =IF(C29>0,"Yes",IF(D29="","Unknown","No")) | C29: =IF(D29="",E29+0,D29) | E29: =COUNTIFS(Planets!$C:$C,I29,Planets!$E:$E,1) | F29: 11.90536 | G29: tau Cet f; tau Cet g; tau Cet h | I29: 8087 | J29: tau Cet | K29: catalog identifier | L29: 3 | M29: 3.6502 | N29: G8V | O29: 0.46644453 | P29: 3.49 | Q29: 8102 | R29: 10700 | S29: 509 | T29: Gl 71 | U29: 52Tau Cet | W29: 26.017185 | X29: -15.93748 | Y29: 10.287243 | Z29: 5.0212035 | AA29: -3.2689349 | AB29: 1 | AC29: 8087 | AD29: 3 | AE29: 0 | AF29: 3.154083 | AG29: 1.539508 | AH29: -1.00226 | AI29: hyg:8087
A30: Gl 54.1 | B30: =IF(C30>0,"Yes",IF(D30="","Unknown","No")) | C30: =IF(D30="",E30+0,D30) | E30: =COUNTIFS(Planets!$C:$C,I30,Planets!$E:$E,1) | F30: 12.034844 | G30: YZ Cet b; YZ Cet c; YZ Cet d | I30: 5632 | J30: YZ Cet | K30: catalog identifier | L30: 0 | M30: 3.6899 | N30: M5.5Ve | O30: 0.00017139573 | P30: 12.1 | Q30: 5643 | T30: Gl 54.1 | W30: 18.12753 | X30: -16.998967 | Y30: 10.938541 | Z30: 3.5811155 | AA30: -3.5186794 | AB30: 1 | AC30: 5632 | AD30: 3 | AE30: 0 | AF30: 3.353772 | AG30: 1.097975 | AH30: -1.078832 | AI30: hyg:5632
A31: HIP 82724 | B31: =IF(C31>0,"Yes",IF(D31="","Unknown","No")) | C31: =IF(D31="",E31+0,D31) | E31: =COUNTIFS(Planets!$C:$C,I31,Planets!$E:$E,1) | F31: 12.056044 | I31: 82472 | L31: 0 | M31: 3.6964 | N31: Mp | O31: 0.00021657085 | P31: 11.85 | Q31: 82724 | W31: 253.63295 | X31: -62.399734 | Y31: -1.5738806 | Z31: -5.3592385 | AA31: -10.684084 | AB31: 1 | AC31: 82472 | AD31: 0 | AE31: 0 | AF31: -0.482554 | AG31: -1.64315 | AH31: -3.275755 | AI31: hyg:82472
A32: Luyten's Star | B32: =IF(C32>0,"Yes",IF(D32="","Unknown","No")) | C32: =IF(D32="",E32+0,D32) | E32: =COUNTIFS(Planets!$C:$C,I32,Planets!$E:$E,1) | F32: 12.402422 | G32: GJ 273 b; GJ 273 c | H32: GJ 273: Catalog distances differ by >20%; HYG controls selection. | I32: 36107 | J32: GJ 273 | K32: catalog identifier | L32: 0 | M32: 3.8026 | N32: M5 | O32: 0.0014588143 | P32: 9.84 | Q32: 36208 | T32: Gl 273 | V32: Luyten's Star | W32: 111.85207 | X32: 5.225785 | Y32: -4.597334 | Z32: 11.463927 | AA32: 1.1296687 | AB32: 1 | AC32: 36107 | AD32: 2 | AE32: 0 | AF32: -1.409549 | AG32: 3.514856 | AH32: 0.346358 | AI32: hyg:36107
A33: Kapteyn's Star | B33: =IF(C33>0,"Yes",IF(D33="","Unknown","No")) | C33: =IF(D33="",E33+0,D33) | E33: =COUNTIFS(Planets!$C:$C,I33,Planets!$E:$E,1) | F33: 12.757281 | G33: Kapteyn c | I33: 24129 | J33: Kapteyn | K33: verified alias | L33: 1 | M33: 3.9114 | N33: M0V | O33: 0.0038089038 | P33: 8.86 | Q33: 24186 | R33: 33793 | T33: Gl 191 | V33: Kapteyn's Star | W33: 77.912535 | X33: -45.018417 | Y33: 1.8884356 | Z33: 8.8230975 | AA33: -9.0287261 | AB33: 1 | AC33: 24129 | AD33: 1 | AE33: 0 | AF33: 0.578997 | AG33: 2.705174 | AH33: -2.76822 | AI33: hyg:24129
A34: Lacaille 8760 | B34: =IF(C34>0,"Yes",IF(D34="","Unknown","No")) | C34: =IF(D34="",E34+0,D34) | E34: =COUNTIFS(Planets!$C:$C,I34,Planets!$E:$E,1) | F34: 12.870783 | I34: 104751 | L34: 0 | M34: 3.9462 | N34: M1/M2V | O34: 0.028602237 | P34: 6.69 | Q34: 105090 | R34: 202560 | T34: Gl 825 | V34: Lacaille 8760 | W34: 319.31587 | X34: -38.867362 | Y34: 7.5994566 | Z34: -6.533421 | AA34: -8.0771877 | AB34: 1 | AC34: 104751 | AD34: 0 | AE34: 0 | AF34: 2.330004 | AG34: -2.003156 | AH34: -2.476477 | AI34: hyg:104751
A35: Kruger 60 | B35: =IF(C35>0,"Yes",IF(D35="","Unknown","No")) | C35: =IF(D35="",E35+0,D35) | E35: =COUNTIFS(Planets!$C:$C,I35,Planets!$E:$E,1) | F35: 13.049517 | I35: 110547 | L35: 0 | M35: 4.001 | N35: M2V | O35: 0.0020342297 | P35: 9.59 | Q35: 110893 | R35: 239960 | T35: Gl 860A | V35: Kruger 60 | W35: 336.99963 | X35: 57.695875 | Y35: 6.4188651 | Z35: -2.7249387 | AA35: 11.028932 | AB35: 1 | AC35: 110547 | AD35: 0 | AE35: 0 | AF35: 1.968033 | AG35: -0.83547 | AH35: 3.381486 | AI35: hyg:110547
A36: Gl 860B | B36: =IF(C36>0,"Yes",IF(D36="","Unknown","No")) | C36: =IF(D36="",E36+0,D36) | E36: =COUNTIFS(Planets!$C:$C,I36,Planets!$E:$E,1) | F36: 13.071369 | I36: 119505 | L36: 0 | M36: 4.0077 | N36: M6 V | O36: 0.0004222795 | P36: 11.3 | T36: Gl 860B | W36: 337.00901 | X36: 57.696623 | Y36: 6.4274007 | Z36: -2.7284481 | AA36: 11.043847 | AB36: 2 | AC36: 110547 | AD36: 0 | AE36: 0 | AF36: 1.97065 | AG36: -0.836546 | AH36: 3.386059 | AI36: hyg:110547
A37: Gl 234B | B37: =IF(C37>0,"Yes",IF(D37="","Unknown","No")) | C37: =IF(D37="",E37+0,D37) | E37: =COUNTIFS(Planets!$C:$C,I37,Planets!$E:$E,1) | F37: 13.428184 | I37: 118428 | L37: 0 | M37: 4.1171 | O37: 2.1340274e-05 | P37: 14.6 | T37: Gl 234B | W37: 97.349085 | X37: -2.812227 | Y37: -1.7155923 | Z37: 13.301838 | AA37: -0.6588261 | AB37: 2 | AC37: 30847 | AD37: 0 | AE37: 0 | AF37: -0.526003 | AG37: 4.078362 | AH37: -0.201997 | AI37: hyg:30847
A38: Ross 614 | B38: =IF(C38>0,"Yes",IF(D38="","Unknown","No")) | C38: =IF(D38="",E38+0,D38) | E38: =COUNTIFS(Planets!$C:$C,I38,Planets!$E:$E,1) | F38: 13.459821 | I38: 30847 | L38: 0 | M38: 4.1268 | N38: M4.5Ve | O38: 0.00052868867 | P38: 11.12 | Q38: 30920 | T38: Gl 234A | V38: Ross 614 | W38: 97.347495 | X38: -2.813979 | Y38: -1.7193203 | Z38: 13.333684 | AA38: -0.66081565 | AB38: 1 | AC38: 30847 | AD38: 0 | AE38: 0 | AF38: -0.527146 | AG38: 4.088126 | AH38: -0.202607 | AI38: hyg:30847
A39: HIP 82725 | B39: =IF(C39>0,"Yes",IF(D39="","Unknown","No")) | C39: =IF(D39="",E39+0,D39) | E39: =COUNTIFS(Planets!$C:$C,I39,Planets!$E:$E,1) | F39: 13.524074 | I39: 82473 | L39: 0 | M39: 4.1465 | O39: 0.00030704357 | P39: 11.72 | Q39: 82725 | W39: 253.63457 | X39: -62.403319 | Y39: -1.7651551 | Z39: -6.0111501 | AA39: -11.985448 | AB39: 1 | AC39: 82473 | AD39: 0 | AE39: 0 | AF39: -0.541199 | AG39: -1.843027 | AH39: -3.674755 | AI39: hyg:82473
A40: Van Maanen's Star | B40: =IF(C40>0,"Yes",IF(D40="","Unknown","No")) | C40: =IF(D40="",E40+0,D40) | E40: =COUNTIFS(Planets!$C:$C,I40,Planets!$E:$E,1) | F40: 13.902742 | I40: 3820 | L40: 0 | M40: 4.2626 | N40: DG | O40: 0.00017831998 | P40: 12.37 | Q40: 3829 | T40: Gl 35 | V40: Van Maanen's Star | W40: 12.29124 | X40: 5.38861 | Y40: 13.525565 | Z40: 2.9468848 | AA40: 1.3057605 | AB40: 1 | AC40: 3820 | AD40: 0 | AE40: 0 | AF40: 4.146957 | AG40: 0.903519 | AH40: 0.400348 | AI40: hyg:3820
...

Sheet Planets
A1: planet_name | B1: host_name | C1: hyg_id | D1: hyg_star_name | E1: include_in_count | F1: notes | G1: semi_major_axis_au | H1: orbital_period_days | I1: eccentricity | J1: insolation_earth | K1: equilibrium_temperature_k | L1: radius_earth | M1: mass_or_msini_earth | N1: stellar_temperature_k | O1: stellar_mass_solar | P1: stellar_radius_solar | Q1: stellar_metallicity_dex | R1: mass_provenance | S1: controversial | T1: discovery_method | U1: discovery_year | V1: nasa_distance_ly | W1: hyg_distance_ly | X1: distance_difference_percent | Y1: match_method | Z1: angular_separation_arcsec | AA1: parameter_selection | AB1: source_rows | AC1: system_planet_count | AD1: system_star_count | AE1: solution_type | AF1: reference | AG1: reference_url | AH1: stellar_reference | AI1: system_reference | AJ1: row_updated | AK1: faction_owners
A2: 61 Vir b | B2: 61 Vir | C2: 64720 | D2: Gl 506 | E2: 1 | G2: 0.050201 | H2: 4.215 | I2: 0.12 | M2: 5.1 | N2: 5577 | O2: 0.942 | P2: 0.963 | Q2: -0.01 | R2: Msini | S2: 0 | T2: Radial Velocity | U2: 2009 | V2: 27.73412 | W2: 27.903004 | X2: 0.60525301 | Y2: catalog identifier | Z2: 23.717508 | AA2: NASA default | AB2: 3 | AC2: 3 | AD2: 1 | AE2: Published Confirmed | AF2: Vogt et al. 2010 | AG2: https://ui.adsabs.harvard.edu/abs/2010ApJ...708.1366V/abstract | AH2: Vogt et al. 2010 | AI2: TICv8 | AJ2: 2014-05-14
A3: 61 Vir c | B3: 61 Vir | C3: 64720 | D3: Gl 506 | E3: 1 | G3: 0.2175 | H3: 38.021 | I3: 0.14 | M3: 18.2 | N3: 5577 | O3: 0.942 | P3: 0.963 | Q3: -0.01 | R3: Msini | S3: 0 | T3: Radial Velocity | U3: 2009 | V3: 27.73412 | W3: 27.903004 | X3: 0.60525301 | Y3: catalog identifier | Z3: 23.717508 | AA3: NASA default | AB3: 3 | AC3: 3 | AD3: 1 | AE3: Published Confirmed | AF3: Vogt et al. 2010 | AG3: https://ui.adsabs.harvard.edu/abs/2010ApJ...708.1366V/abstract | AH3: Vogt et al. 2010 | AI3: TICv8 | AJ3: 2014-05-14
A4: 61 Vir d | B4: 61 Vir | C4: 64720 | D4: Gl 506 | E4: 1 | G4: 0.476 | H4: 123.01 | I4: 0.35 | M4: 22.9 | N4: 5577 | O4: 0.942 | P4: 0.963 | Q4: -0.01 | R4: Msini | S4: 0 | T4: Radial Velocity | U4: 2009 | V4: 27.73412 | W4: 27.903004 | X4: 0.60525301 | Y4: catalog identifier | Z4: 23.717508 | AA4: NASA default | AB4: 2 | AC4: 3 | AD4: 1 | AE4: Published Confirmed | AF4: Vogt et al. 2010 | AG4: https://ui.adsabs.harvard.edu/abs/2010ApJ...708.1366V/abstract | AH4: Vogt et al. 2010 | AI4: TICv8 | AJ4: 2014-05-14
A5: Barnard b | B5: Barnard's star | C5: 87665 | D5: Barnard's Star | E5: 1 | G5: 0.0229 | H5: 3.1542 | I5: 0.03 | K5: 438 | M5: 0.299 | N5: 3195 | O5: 0.162 | P5: 0.185 | Q5: -0.56 | R5: Msini | S5: 0 | T5: Radial Velocity | U5: 2024 | V5: 5.9574093 | W5: 5.94844 | X5: 0.15078408 | Y5: catalog identifier | Z5: 161.01489 | AA5: NASA default | AB5: 2 | AC5: 4 | AD5: 1 | AE5: Published Confirmed | AF5: Basant et al. 2025 | AG5: https://ui.adsabs.harvard.edu/abs/2025ApJ...982L...1B/abstract | AH5: González Hernández et al. 2024 | AI5: TICv8 | AJ5: 2025-03-10
A6: Barnard c | B6: Barnard's star | C6: 87665 | D6: Barnard's Star | E6: 1 | G6: 0.0274 | H6: 4.1244 | I6: 0.08 | K6: 400 | M6: 0.335 | N6: 3195 | O6: 0.162 | P6: 0.185 | Q6: -0.56 | R6: Msini | S6: 0 | T6: Radial Velocity | U6: 2025 | V6: 5.9574093 | W6: 5.94844 | X6: 0.15078408 | Y6: catalog identifier | Z6: 161.01489 | AA6: NASA default | AB6: 1 | AC6: 4 | AD6: 1 | AE6: Published Confirmed | AF6: Basant et al. 2025 | AG6: https://ui.adsabs.harvard.edu/abs/2025ApJ...982L...1B/abstract | AH6: González Hernández et al. 2024 | AI6: TICv8 | AJ6: 2025-03-10
A7: Barnard d | B7: Barnard's star | C7: 87665 | D7: Barnard's Star | E7: 1 | G7: 0.0188 | H7: 2.3402 | I7: 0.04 | K7: 483 | M7: 0.263 | N7: 3195 | O7: 0.162 | P7: 0.185 | Q7: -0.56 | R7: Msini | S7: 0 | T7: Radial Velocity | U7: 2025 | V7: 5.9574093 | W7: 5.94844 | X7: 0.15078408 | Y7: catalog identifier | Z7: 161.01489 | AA7: NASA default | AB7: 1 | AC7: 4 | AD7: 1 | AE7: Published Confirmed | AF7: Basant et al. 2025 | AG7: https://ui.adsabs.harvard.edu/abs/2025ApJ...982L...1B/abstract | AH7: González Hernández et al. 2024 | AI7: TICv8 | AJ7: 2025-03-10
A8: Barnard e | B8: Barnard's star | C8: 87665 | D8: Barnard's Star | E8: 1 | G8: 0.0381 | H8: 6.7392 | I8: 0.04 | K8: 340 | M8: 0.193 | N8: 3195 | O8: 0.162 | P8: 0.185 | Q8: -0.56 | R8: Msini | S8: 0 | T8: Radial Velocity | U8: 2025 | V8: 5.9574093 | W8: 5.94844 | X8: 0.15078408 | Y8: catalog identifier | Z8: 161.01489 | AA8: NASA default | AB8: 1 | AC8: 4 | AD8: 1 | AE8: Published Confirmed | AF8: Basant et al. 2025 | AG8: https://ui.adsabs.harvard.edu/abs/2025ApJ...982L...1B/abstract | AH8: González Hernández et al. 2024 | AI8: TICv8 | AJ8: 2025-03-10
A9: CD Cet b | B9: CD Cet | C9: 118201 | D9: GJ 1057 | E9: 1 | G9: 0.0185 | H9: 2.2907 | J9: 8.6 | K9: 464 | M9: 3.95 | N9: 3130 | O9: 0.161 | P9: 0.175 | Q9: 0.13 | R9: Msini | S9: 0 | T9: Radial Velocity | U9: 2020 | V9: 28.072769 | W9: 27.616965 | X9: 1.6504476 | Y9: verified alias | Z9: 36.75496 | AA9: NASA default | AB9: 1 | AC9: 1 | AD9: 1 | AE9: Published Confirmed | AF9: Bauer et al. 2020 | AG9: https://ui.adsabs.harvard.edu/abs/2020A&A...640A..50B/abstract | AH9: Bauer et al. 2020 | AI9: TICv8 | AJ9: 2021-11-02
A10: GJ 1002 b | B10: GJ 1002 | C10: 117960 | D10: GJ 1002 | E10: 1 | G10: 0.0457 | H10: 10.3465 | J10: 0.67 | K10: 230.9 | M10: 1.08 | N10: 3024 | O10: 0.12 | P10: 0.137 | Q10: -0.25 | R10: Msini | S10: 0 | T10: Radial Velocity | U10: 2022 | V10: 15.814246 | W10: 15.326741 | X10: 3.1807542 | Y10: catalog identifier | Z10: 32.501943 | AA10: NASA default | AB10: 1 | AC10: 2 | AD10: 1 | AE10: Published Confirmed | AF10: Suárez Mascareño et al. 2023 | AG10: https://ui.adsabs.harvard.edu/abs/2023A&A...670A...5S/abstract | AH10: Suárez Mascareño et al. 2023 | AI10: TICv8 | AJ10: 2022-12-17
A11: GJ 1002 c | B11: GJ 1002 | C11: 117960 | D11: GJ 1002 | E11: 1 | G11: 0.0738 | H11: 21.202 | J11: 0.257 | K11: 181.7 | M11: 1.36 | N11: 3024 | O11: 0.12 | P11: 0.137 | Q11: -0.25 | R11: Msini | S11: 0 | T11: Radial Velocity | U11: 2022 | V11: 15.814246 | W11: 15.326741 | X11: 3.1807542 | Y11: catalog identifier | Z11: 32.501943 | AA11: NASA default | AB11: 1 | AC11: 2 | AD11: 1 | AE11: Published Confirmed | AF11: Suárez Mascareño et al. 2023 | AG11: https://ui.adsabs.harvard.edu/abs/2023A&A...670A...5S/abstract | AH11: Suárez Mascareño et al. 2023 | AI11: TICv8 | AJ11: 2022-12-17
A12: GJ 1061 b | B12: GJ 1061 | C12: 118236 | D12: GJ 1061 | E12: 1 | G12: 0.021 | H12: 3.2073 | I12: 0.05 | M12: 1.11 | N12: 2953 | O12: 0.12 | P12: 0.156 | Q12: -0.08 | R12: Mass | S12: 0 | T12: Radial Velocity | U12: 2020 | V12: 11.979006 | W12: 13.997979 | X12: 14.423319 | Y12: catalog identifier | Z12: 21.565206 | AA12: NASA default | AB12: 2 | AC12: 3 | AD12: 1 | AE12: Published Confirmed | AF12: Dreizler et al. 2025 | AG12: https://ui.adsabs.harvard.edu/abs/2025A&A...698A.114D/abstract | AH12: Dreizler et al. 2025 | AI12: TICv8 | AJ12: 2026-03-12
A13: GJ 1061 c | B13: GJ 1061 | C13: 118236 | D13: GJ 1061 | E13: 1 | G13: 0.0342 | H13: 6.6821 | I13: 0.02 | M13: 1.81 | N13: 2953 | O13: 0.12 | P13: 0.156 | Q13: -0.08 | R13: Mass | S13: 0 | T13: Radial Velocity | U13: 2020 | V13: 11.979006 | W13: 13.997979 | X13: 14.423319 | Y13: catalog identifier | Z13: 21.565206 | AA13: NASA default | AB13: 2 | AC13: 3 | AD13: 1 | AE13: Published Confirmed | AF13: Dreizler et al. 2025 | AG13: https://ui.adsabs.harvard.edu/abs/2025A&A...698A.114D/abstract | AH13: Dreizler et al. 2025 | AI13: TICv8 | AJ13: 2026-03-12
A14: GJ 1061 d | B14: GJ 1061 | C14: 118236 | D14: GJ 1061 | E14: 1 | G14: 0.054 | H14: 13.066 | I14: 0.04 | M14: 1.67 | N14: 2953 | O14: 0.12 | P14: 0.156 | Q14: -0.08 | R14: Mass | S14: 0 | T14: Radial Velocity | U14: 2020 | V14: 11.979006 | W14: 13.997979 | X14: 14.423319 | Y14: catalog identifier | Z14: 21.565206 | AA14: NASA default | AB14: 2 | AC14: 3 | AD14: 1 | AE14: Published Confirmed | AF14: Dreizler et al. 2025 | AG14: https://ui.adsabs.harvard.edu/abs/2025A&A...698A.114D/abstract | AH14: Dreizler et al. 2025 | AI14: TICv8 | AJ14: 2026-03-12
A15: GJ 1151 c | B15: GJ 1151 | C15: 118777 | D15: GJ 1151 | E15: 1 | G15: 0.5714 | H15: 389.7 | M15: 10.62 | N15: 3280 | O15: 0.1639 | P15: 0.1781 | Q15: -0.12 | R15: Msini | S15: 0 | T15: Radial Velocity | U15: 2023 | V15: 26.210742 | W15: 26.778091 | X15: 2.118706 | Y15: catalog identifier | Z15: 61.416018 | AA15: NASA default | AB15: 1 | AC15: 1 | AD15: 1 | AE15: Published Confirmed | AF15: Blanco-Pozo et al. 2023 | AG15: https://ui.adsabs.harvard.edu/abs/2023A&A...671A..50B/abstract | AH15: Blanco-Pozo et al. 2023 | AI15: TICv8 | AJ15: 2023-01-23
A16: GJ 1289 b | B16: GJ 1289 | C16: 119588 | D16: GJ 1289 | E16: 1 | G16: 0.27 | H16: 111.74 | I16: 0 | K16: 150 | M16: 6.27 | N16: 3296 | O16: 0.21 | Q16: 0.02 | R16: Msini | S16: 0 | T16: Radial Velocity | U16: 2024 | V16: 27.238852 | W16: 26.51684 | X16: 2.7228447 | Y16: catalog identifier | Z16: 23.815826 | AA16: NASA default | AB16: 1 | AC16: 1 | AD16: 1 | AE16: Published Confirmed | AF16: Moutou et al. 2024 | AG16: https://ui.adsabs.harvard.edu/abs/2024A&A...688A.196M/abstract | AH16: Moutou et al. 2024 | AI16: TICv8 | AJ16: 2025-03-18
A17: GJ 15 A b | B17: GJ 15 A | C17: 1472 | D17: Groombridge 34 | E17: 1 | G17: 0.072 | H17: 11.4407 | I17: 0.094 | M17: 3.03 | N17: 3607 | O17: 0.38 | P17: 0.38 | Q17: -0.34 | R17: Msini | S17: 1 | T17: Radial Velocity | U17: 2014 | V17: 11.618603 | W17: 11.700208 | X17: 0.69746049 | Y17: catalog identifier | Z17: 52.31301 | AA17: NASA default | AB17: 3 | AC17: 2 | AD17: 2 | AE17: Published Confirmed | AF17: Pinamonti et al. 2018 | AG17: https://ui.adsabs.harvard.edu/abs/2018A&A...617A.104P/abstract | AH17: Pinamonti et al. 2018 | AI17: TICv8 | AJ17: 2019-10-02
A18: GJ 15 A c | B18: GJ 15 A | C18: 1472 | D18: Groombridge 34 | E18: 1 | G18: 5.4 | H18: 7600 | I18: 0.27 | M18: 36 | N18: 3607 | O18: 0.38 | P18: 0.38 | Q18: -0.34 | R18: Msini | S18: 0 | T18: Radial Velocity | U18: 2018 | V18: 11.618603 | W18: 11.700208 | X18: 0.69746049 | Y18: catalog identifier | Z18: 52.31301 | AA18: NASA default | AB18: 1 | AC18: 2 | AD18: 2 | AE18: Published Confirmed | AF18: Pinamonti et al. 2018 | AG18: https://ui.adsabs.harvard.edu/abs/2018A&A...617A.104P/abstract | AH18: Pinamonti et al. 2018 | AI18: TICv8 | AJ18: 2019-10-02
A19: GJ 229 A c | B19: GJ 229 | C19: 29222 | D19: Gl 229 | E19: 1 | G19: 0.384 | H19: 121.93268 | I19: 0.366 | M19: 8.581367 | O19: 0.509 | R19: Msini | S19: 1 | T19: Radial Velocity | U19: 2020 | V19: 18.774344 | W19: 18.765081 | X19: 0.049362116 | Y19: catalog identifier | Z19: 11.306649 | AA19: NASA default | AB19: 2 | AC19: 2 | AD19: 3 | AE19: Published Confirmed | AF19: Feng et al. 2022 | AG19: https://ui.adsabs.harvard.edu/abs/2022ApJS..262...21F/abstract | AH19: Feng et al. 2022 | AI19: TICv8 | AJ19: 2023-06-14
A20: GJ 229 b | B20: GJ 229 | C20: 29222 | D20: Gl 229 | E20: 1 | G20: 1.086 | H20: 579.47495 | I20: 0.404 | M20: 14.937935 | O20: 0.509 | R20: Msini | S20: 1 | T20: Radial Velocity | U20: 2014 | V20: 18.774344 | W20: 18.765081 | X20: 0.049362116 | Y20: catalog identifier | Z20: 11.306649 | AA20: NASA default | AB20: 3 | AC20: 2 | AD20: 3 | AE20: Published Confirmed | AF20: Feng et al. 2022 | AG20: https://ui.adsabs.harvard.edu/abs/2022ApJS..262...21F/abstract | AH20: Feng et al. 2022 | AI20: TICv8 | AJ20: 2023-06-14
A21: GJ 251 b | B21: GJ 251 | C21: 118447 | D21: Gl 251 | E21: 1 | G21: 0.0808 | H21: 14.237 | I21: 0 | J21: 2.37 | K21: 336 | M21: 3.85 | N21: 3342 | O21: 0.35 | P21: 0.36 | Q21: 0.07 | R21: Msini | S21: 0 | T21: Radial Velocity | U21: 2020 | V21: 18.201385 | W21: 18.787912 | X21: 3.1218318 | Y21: catalog identifier | Z21: 19.189104 | AA21: NASA default | AB21: 2 | AC21: 2 | AD21: 1 | AE21: Published Confirmed | AF21: Beard et al. 2025 | AG21: https://ui.adsabs.harvard.edu/abs/2025AJ....170..279B/abstract | AH21: Beard et al. 2025 | AI21: TICv8 | AJ21: 2025-10-30
A22: GJ 251 c | B22: GJ 251 | C22: 118447 | D22: Gl 251 | E22: 1 | G22: 0.196 | H22: 53.647 | I22: 0 | J22: 0.404 | K22: 216 | M22: 3.88 | N22: 3342 | O22: 0.35 | P22: 0.36 | Q22: 0.07 | R22: Msini | S22: 0 | T22: Radial Velocity | U22: 2025 | V22: 18.201385 | W22: 18.787912 | X22: 3.1218318 | Y22: catalog identifier | Z22: 19.189104 | AA22: NASA default | AB22: 1 | AC22: 2 | AD22: 1 | AE22: Published Confirmed | AF22: Beard et al. 2025 | AG22: https://ui.adsabs.harvard.edu/abs/2025AJ....170..279B/abstract | AH22: Beard et al. 2025 | AI22: TICv8 | AJ22: 2025-10-30
A23: GJ 273 b | B23: GJ 273 | C23: 36107 | D23: Luyten's Star | E23: 1 | G23: 0.091101 | H23: 18.6498 | I23: 0.1 | J23: 1.06 | M23: 2.89 | N23: 3382 | O23: 0.29 | P23: 0.293 | Q23: 0.09 | R23: Msini | S23: 0 | T23: Radial Velocity | U23: 2017 | V23: 19.313464 | W23: 12.402422 | X23: 55.723321 | Y23: catalog identifier | Z23: 0.097789962 | AA23: NASA default | AB23: 1 | AC23: 2 | AD23: 1 | AE23: Published Confirmed | AF23: Astudillo-Defru et al. 2017 | AG23: https://ui.adsabs.harvard.edu/abs/2017A&A...602A..88A/abstract | AH23: Astudillo-Defru et al. 2017 | AI23: TICv8 | AJ23: 2017-03-29
A24: GJ 273 c | B24: GJ 273 | C24: 36107 | D24: Luyten's Star | E24: 1 | G24: 0.036467 | H24: 4.7234 | I24: 0.17 | J24: 6.66 | M24: 1.18 | N24: 3382 | O24: 0.29 | P24: 0.293 | Q24: 0.09 | R24: Msini | S24: 0 | T24: Radial Velocity | U24: 2017 | V24: 19.313464 | W24: 12.402422 | X24: 55.723321 | Y24: catalog identifier | Z24: 0.097789962 | AA24: NASA default | AB24: 1 | AC24: 2 | AD24: 1 | AE24: Published Confirmed | AF24: Astudillo-Defru et al. 2017 | AG24: https://ui.adsabs.harvard.edu/abs/2017A&A...602A..88A/abstract | AH24: Astudillo-Defru et al. 2017 | AI24: TICv8 | AJ24: 2017-03-29
A25: GJ 3323 b | B25: GJ 3323 | C25: 118344 | D25: GJ 3323 | E25: 1 | G25: 0.03282 | H25: 5.3636 | I25: 0.23 | J25: 2.58 | M25: 2.02 | N25: 3159 | O25: 0.164 | P25: 0.119 | Q25: -0.27 | R25: Msini | S25: 0 | T25: Radial Velocity | U25: 2017 | V25: 17.530383 | W25: 20.009694 | X25: 12.390546 | Y25: catalog identifier | Z25: 12.506581 | AA25: NASA default | AB25: 1 | AC25: 2 | AD25: 1 | AE25: Published Confirmed | AF25: Astudillo-Defru et al. 2017 | AG25: https://ui.adsabs.harvard.edu/abs/2017A&A...602A..88A/abstract | AH25: Astudillo-Defru et al. 2017 | AI25: TICv8 | AJ25: 2017-03-29
A26: GJ 3323 c | B26: GJ 3323 | C26: 118344 | D26: GJ 3323 | E26: 1 | G26: 0.1264 | H26: 40.54 | I26: 0.17 | J26: 0.17 | M26: 2.31 | N26: 3159 | O26: 0.164 | P26: 0.119 | Q26: -0.27 | R26: Msini | S26: 0 | T26: Radial Velocity | U26: 2017 | V26: 17.530383 | W26: 20.009694 | X26: 12.390546 | Y26: catalog identifier | Z26: 12.506581 | AA26: NASA default | AB26: 1 | AC26: 2 | AD26: 1 | AE26: Published Confirmed | AF26: Astudillo-Defru et al. 2017 | AG26: https://ui.adsabs.harvard.edu/abs/2017A&A...602A..88A/abstract | AH26: Astudillo-Defru et al. 2017 | AI26: TICv8 | AJ26: 2017-03-29
A27: GJ 3378 b | B27: GJ 3378 | C27: 118405 | D27: GJ 3378 | E27: 1 | G27: 0.09673 | H27: 21.45 | I27: 0 | J27: 0.91 | K27: 272 | M27: 2.3 | N27: 3340 | O27: 0.262 | P27: 0.275 | Q27: -0.09 | R27: Msini | S27: 0 | T27: Radial Velocity | U27: 2026 | V27: 25.188209 | W27: 24.671447 | X27: 2.0945758 | Y27: catalog identifier | Z27: 28.603915 | AA27: NASA default | AB27: 2 | AC27: 1 | AD27: 1 | AE27: Published Confirmed | AF27: Robertson et al. 2026 | AG27: https://ui.adsabs.harvard.edu/abs/2026ApJ..1005...32R/abstract | AH27: Robertson et al. 2026 | AI27: TICv8 | AJ27: 2026-06-04
A28: GJ 338 B b | B28: GJ 338 B | C28: 45214 | D28: Gl 338B | E28: 1 | G28: 0.142 | H28: 24.422 | I28: 0.109 | M28: 10.6 | N28: 4014 | O28: 0.64 | P28: 0.58 | Q28: -0.03 | R28: Msini | S28: 0 | T28: Radial Velocity | U28: 2020 | V28: 20.654048 | W28: 20.847263 | X28: 0.92681248 | Y28: catalog identifier | Z28: 31.579368 | AA28: NASA default | AB28: 2 | AC28: 1 | AD28: 2 | AE28: Published Confirmed | AF28: DiTomasso et al. 2023 | AG28: https://ui.adsabs.harvard.edu/abs/2023AJ....165...38D/abstract | AH28: DiTomasso et al. 2023 | AI28: TICv8 | AJ28: 2023-01-18
A29: GJ 357 b | B29: GJ 357 | C29: 46970 | D29: Gl 357 | E29: 1 | G29: 0.036 | H29: 3.9306 | K29: 518 | L29: 1.2 | N29: 3505 | O29: 0.342 | P29: 0.337 | Q29: -0.12 | S29: 0 | T29: Transit | U29: 2019 | V29: 30.795065 | W29: 29.431047 | X29: 4.6346248 | Y29: catalog identifier | Z29: 15.521472 | AA29: NASA default | AB29: 6 | AC29: 3 | AD29: 1 | AE29: Published Confirmed | AF29: Oddo et al. 2023 | AG29: https://ui.adsabs.harvard.edu/abs/2023AJ....165..134O/abstract | AH29: Oddo et al. 2023 | AI29: TICv8 | AJ29: 2023-08-22
A30: GJ 357 c | B30: GJ 357 | C30: 46970 | D30: Gl 357 | E30: 1 | G30: 0.061 | H30: 9.1247 | J30: 4.45 | K30: 401.2 | M30: 3.4 | N30: 3505 | O30: 0.342 | P30: 0.337 | Q30: -0.12 | R30: Msini | S30: 0 | T30: Radial Velocity | U30: 2019 | V30: 30.795065 | W30: 29.431047 | X30: 4.6346248 | Y30: catalog identifier | Z30: 15.521472 | AA30: NASA default | AB30: 1 | AC30: 3 | AD30: 1 | AE30: Published Confirmed | AF30: Luque et al. 2019 | AG30: https://ui.adsabs.harvard.edu/abs/2019A&A...628A..39L/abstract | AH30: Luque et al. 2019 | AI30: TICv8 | AJ30: 2019-07-29
A31: GJ 357 d | B31: GJ 357 | C31: 46970 | D31: Gl 357 | E31: 1 | G31: 0.204 | H31: 55.661 | J31: 0.38 | K31: 219.6 | M31: 6.1 | N31: 3505 | O31: 0.342 | P31: 0.337 | Q31: -0.12 | R31: Msini | S31: 0 | T31: Radial Velocity | U31: 2019 | V31: 30.795065 | W31: 29.431047 | X31: 4.6346248 | Y31: catalog identifier | Z31: 15.521472 | AA31: NASA default | AB31: 1 | AC31: 3 | AD31: 1 | AE31: Published Confirmed | AF31: Luque et al. 2019 | AG31: https://ui.adsabs.harvard.edu/abs/2019A&A...628A..39L/abstract | AH31: Luque et al. 2019 | AI31: TICv8 | AJ31: 2019-07-29
A32: GJ 393 b | B32: GJ 393 | C32: 51172 | D32: Gl 393 | E32: 1 | G32: 0.05402 | H32: 7.02679 | J32: 9.21 | K32: 485 | M32: 1.71 | N32: 3579 | O32: 0.426 | P32: 0.426 | Q32: -0.09 | R32: Msini | S32: 0 | T32: Radial Velocity | U32: 2021 | V32: 22.933653 | W32: 23.049797 | X32: 0.5038842 | Y32: catalog identifier | Z32: 14.713859 | AA32: NASA default | AB32: 1 | AC32: 1 | AD32: 1 | AE32: Published Confirmed | AF32: Amado et al. 2021 | AG32: https://ui.adsabs.harvard.edu/abs/2021A&A...650A.188A/abstract | AH32: Amado et al. 2021 | AI32: TICv8 | AJ32: 2021-07-12
A33: GJ 411 b | B33: GJ 411 | C33: 53879 | D33: Lalande 21185 | E33: 1 | G33: 0.07879 | H33: 12.9394 | I33: 0.063 | M33: 2.69 | N33: 3719 | O33: 0.3899 | P33: 0.3685 | Q33: -0.3621 | R33: Msini | S33: 0 | T33: Radial Velocity | U33: 2019 | V33: 18.511896 | W33: 8.3068768 | X33: 122.85025 | Y33: catalog identifier | Z33: 8.7840391 | AA33: NASA default | AB33: 5 | AC33: 2 | AD33: 1 | AE33: Published Confirmed | AF33: Hurt et al. 2022 | AG33: https://ui.adsabs.harvard.edu/abs/2022AJ....163..218H/abstract | AH33: Hurt et al. 2022 | AI33: TICv8 | AJ33: 2022-05-24
A34: GJ 4274 b | B34: GJ 4274 | C34: 119492 | D34: GJ 4274 | E34: 1 | G34: 0.0153 | H34: 1.6339 | J34: 14.7 | M34: 2.97 | N34: 3228 | O34: 0.18 | P34: 0.19 | Q34: -0.19 | R34: Msini | S34: 0 | T34: Radial Velocity | U34: 2026 | V34: 23.59924 | W34: 24.321807 | X34: 2.97086 | Y34: catalog identifier | Z34: 14.356325 | AA34: NASA default | AB34: 1 | AC34: 2 | AD34: 1 | AE34: Published Confirmed | AF34: Charpentier et al. 2026 | AG34: https://ui.adsabs.harvard.edu/abs/2026A&A...705A.243C/abstract | AH34: Charpentier et al. 2026 | AI34: TICv8 | AJ34: 2026-02-12
A35: GJ 4274 c | B35: GJ 4274 | C35: 119492 | D35: GJ 4274 | E35: 1 | G35: 0.186 | H35: 69.57 | J35: 0.1 | M35: 8.39 | N35: 3228 | O35: 0.18 | P35: 0.19 | Q35: -0.19 | R35: Msini | S35: 0 | T35: Radial Velocity | U35: 2026 | V35: 23.59924 | W35: 24.321807 | X35: 2.97086 | Y35: catalog identifier | Z35: 14.356325 | AA35: NASA default | AB35: 1 | AC35: 2 | AD35: 1 | AE35: Published Confirmed | AF35: Charpentier et al. 2026 | AG35: https://ui.adsabs.harvard.edu/abs/2026A&A...705A.243C/abstract | AH35: Charpentier et al. 2026 | AI35: TICv8 | AJ35: 2026-02-12
A36: GJ 433 b | B36: GJ 433 | C36: 56359 | D36: Gl 433 | E36: 1 | G36: 0.062 | H36: 7.3705 | I36: 0.04 | M36: 6.043 | O36: 0.48 | R36: Msini | S36: 0 | T36: Radial Velocity | U36: 2013 | V36: 29.564641 | W36: 28.971166 | X36: 2.0484993 | Y36: catalog identifier | Z36: 13.22413 | AA36: NASA default | AB36: 4 | AC36: 3 | AD36: 1 | AE36: Published Confirmed | AF36: Feng et al. 2020 | AG36: https://ui.adsabs.harvard.edu/abs/2020ApJS..246...11F/abstract | AH36: Feng et al. 2020 | AI36: TICv8 | AJ36: 2020-02-06
A37: GJ 433 c | B37: GJ 433 | C37: 56359 | D37: Gl 433 | E37: 1 | G37: 4.819 | H37: 5094.105 | I37: 0.12 | M37: 32.422 | O37: 0.48 | R37: Msini | S37: 0 | T37: Radial Velocity | U37: 2014 | V37: 29.564641 | W37: 28.971166 | X37: 2.0484993 | Y37: catalog identifier | Z37: 13.22413 | AA37: NASA default | AB37: 2 | AC37: 3 | AD37: 1 | AE37: Published Confirmed | AF37: Feng et al. 2020 | AG37: https://ui.adsabs.harvard.edu/abs/2020ApJS..246...11F/abstract | AH37: Feng et al. 2020 | AI37: TICv8 | AJ37: 2020-02-07
A38: GJ 433 d | B38: GJ 433 | C38: 56359 | D38: Gl 433 | E38: 1 | G38: 0.178 | H38: 36.059 | I38: 0.07 | M38: 5.223 | O38: 0.48 | R38: Msini | S38: 0 | T38: Radial Velocity | U38: 2020 | V38: 29.564641 | W38: 28.971166 | X38: 2.0484993 | Y38: catalog identifier | Z38: 13.22413 | AA38: NASA default | AB38: 1 | AC38: 3 | AD38: 1 | AE38: Published Confirmed | AF38: Feng et al. 2020 | AG38: https://ui.adsabs.harvard.edu/abs/2020ApJS..246...11F/abstract | AH38: Feng et al. 2020 | AI38: TICv8 | AJ38: 2020-02-06
A39: GJ 486 b | B39: GJ 486 | C39: 62257 | D39: Gar | E39: 1 | G39: 0.01714 | H39: 1.4671213 | I39: 0.00086 | J39: 39.2 | K39: 696.3 | L39: 1.289 | M39: 2.77 | N39: 3317 | O39: 0.312 | P39: 0.3243 | Q39: -0.15 | R39: Mass | S39: 0 | T39: Radial Velocity | U39: 2021 | V39: 26.334714 | W39: 27.300267 | X39: 3.5367908 | Y39: catalog identifier | Z39: 17.302015 | AA39: NASA default | AB39: 4 | AC39: 1 | AD39: 1 | AE39: Published Confirmed | AF39: Weiner Mansfield et al. 2024 | AG39: https://ui.adsabs.harvard.edu/abs/2024ApJ...975L..22W/abstract | AH39: Weiner Mansfield et al. 2024 | AI39: TICv8 | AJ39: 2025-04-16
A40: GJ 514 b | B40: GJ 514 | C40: 65653 | D40: Gl 514 | E40: 1 | G40: 0.422 | H40: 140.43 | I40: 0.45 | J40: 0.28 | K40: 202 | M40: 5.2 | N40: 3728 | O40: 0.51 | P40: 0.5 | Q40: -0.14 | R40: Msini | S40: 0 | T40: Radial Velocity | U40: 2022 | V40: 24.845875 | W40: 24.96988 | X40: 0.49661694 | Y40: catalog identifier | Z40: 24.229312 | AA40: NASA default | AB40: 1 | AC40: 1 | AD40: 1 | AE40: Published Confirmed | AF40: Damasso et al. 2022 | AG40: https://ui.adsabs.harvard.edu/abs/2022A&A...666A.187D/abstract | AH40: Damasso et al. 2022 | AI40: TICv8 | AJ40: 2022-04-19
...

Sheet Factions
A1: faction_id | B1: faction_name | C1: color | D1: notes

Sheet Read me
A1: topic | B1: description
A2: Faction ownership | B2: Factions: define faction_id, faction_name, #RRGGBB color and notes. Stars/Planets faction_owners: semicolon-separated IDs, e.g. union; league. Blank means no recorded ownership. Stars sharing system_id share the union of their star-level claims. Planet owners are independent and never inherited. system_id defaults to the HYG primary and can be edited to group components. These are fictional campaign annotations, not astronomical data. Regeneration preserves campaign fields and user count/notes edits from the existing output workbook, or from --campaign-from when specified.
A3: Editing | B3: Stars: yellow planet_count_override accepts a count; leave blank to count Planets. Yellow notes cells are free text. Planets: include_in_count=0 excludes a row. Formulas update in Excel/LibreOffice.
A4: Planet status | B4: Yes means at least one counted planet. Unknown means no confirmed exoplanet was matched in these files. Explicit count override 0 displays No (your assertion). archive_planet_count preserves the original matched count.
A5: Counts | B5: Count distinct pl_name values, not publication rows or sy_pnum (which is system-wide). Controversial archive members remain included and flagged. Sol has 8 known planets but 0 exoplanets; Solar System orbital data are not supplied.
A6: Naming | B6: Preserve NASA scientific designations exactly. Host + existing lowercase planet letter; letters reflect discovery order, not orbital distance. Uppercase stellar components remain distinct. HYG proper names are display labels, not newly assigned IAU names.
A7: Selection | B7: HYG distance in parsecs controls the inclusive radius cut; missing/nonfinite/negative/sentinel distances are excluded. HYG is not a complete census and can contain duplicates. Rows are HYG entries, not deduplicated physical stars.
A8: Cartesian coordinates | B8: Stars includes x_ly/y_ly/z_ly in light-years and x_pc/y_pc/z_pc in parsecs. These are HYG heliocentric J2000 equatorial coordinates: +X toward the vernal equinox, +Y toward RA 6 hours, +Z toward the north celestial pole. Sol is pinned to exactly (0,0,0); other HYG positions are preserved.
A9: Matching | B9: Exact normalized catalog, Bayer, Flamsteed, variable or proper name, then explicit verified aliases. Never assign by angular proximity alone; Review lists candidates. Matches outside the radius are retained in Host matches.
A10: Distance checks | B10: NASA and HYG distances can differ substantially; >20% differences are flagged. Angular separations are diagnostic only: epochs/proper motion can differ. No positions are propagated.
A11: Measurements | B11: Planets uses one default NASA row per planet. If absent, latest row is used and flagged. No values are filled from other publications. Measurements retains all published rows, errors, limits and references for matched planets; used_in_planets=1 marks chosen rows.
A12: Habitability | B12: Semi-major axis is orbital size, not instantaneous separation. Published flux and equilibrium temperature are indicators, not habitability verdicts; equilibrium temperature is not surface temperature. Mass may be M sin(i), indicated by mass_provenance. Blank means unavailable. See Measurements for uncertainty and limit flags.
... A37: campaign_source | B37: nearby_stars.xlsx

Sheet Review
A1: nasa_host | B1: planet_count | C1: status | D1: hyg_id | E1: hyg_name | F1: hyg_distance_ly | G1: nasa_distance_ly | H1: method | I1: evidence | J1: angular_separation_arcsec | K1: distance_difference_percent | L1: candidate_hyg_ids | M1: notes
A2: GJ 273 | B2: 2 | C2: matched_selected | D2: 36107 | E2: Luyten's Star | F2: 12.402422 | G2: 19.313464 | H2: catalog identifier | I2: GJ 273 | J2: 0.097789962 | K2: 55.723321 | M2: Catalog distances differ by >20%; HYG controls selection.
A3: GJ 411 | B3: 2 | C3: matched_selected | D3: 53879 | E3: Lalande 21185 | F3: 8.3068768 | G3: 18.511896 | H3: catalog identifier | I3: GJ 411 | J3: 8.7840391 | K3: 122.85025 | M3: Catalog distances differ by >20%; HYG controls selection.
A4: Gl 725 B | B4: 1 | C4: matched_selected | D4: 91487 | E4: Struve 2398 B | F4: 11.267072 | G4: 22.316784 | H4: catalog identifier | I4: Gl 725 B | J4: 6.2036936 | K4: 98.070835 | M4: Catalog distances differ by >20%; HYG controls selection.
A5: LTT 1445 A | B5: 2 | C5: unmatched_nearby | G5: 22.404627 | H5: unassigned | I5: LTT 1445 A | L5: 118187; 119616 | M5: Position candidates require review; component identity is preserved.
A6: RR Cae | B6: 1 | C6: matched_selected | D6: 118293 | E6: GJ 2034 | F6: 26.51684 | G6: 69.117755 | H6: verified alias | I6: GJ 2034; https://simbad.u-strasbg.fr/simbad/sim-basic?Ident=rr+cae&submit=SIMBAD+search; Unresolved binary system entry; HYG distance differs substantially from NASA | J6: 49.7818 | K6: 160.65608 | M6: Catalog distances differ by >20%; HYG controls selection.
A7: Teegarden's Star | B7: 3 | C7: unmatched_nearby | G7: 12.494333 | H7: unassigned | I7: Teegarden's Star | M7: Position candidates require review; component identity is preserved.

Sheet Host matches
A1: nasa_host | B1: planet_count | C1: status | D1: hyg_id | E1: hyg_name | F1: hyg_distance_ly | G1: nasa_distance_ly | H1: method | I1: evidence | J1: angular_separation_arcsec | K1: distance_difference_percent | L1: candidate_hyg_ids | M1: notes
A2: 11 Com | B2: 1 | C2: matched_outside_radius | D2: 60017 | E2: 11 Com | F2: 289.91682 | G2: 303.92752 | H2: catalog identifier | I2: 11 Com | J2: 2.2297019 | K2: 4.8326619
A3: 11 UMi | B3: 1 | C3: matched_outside_radius | D3: 74564 | E3: 11 UMi | F3: 398.23726 | G3: 408.74243 | H3: catalog identifier | I3: 11 UMi | J3: 0.17266634 | K3: 2.6379176
A4: 14 And | B4: 1 | C4: matched_outside_radius | D4: 115711 | E4: Veritate | F4: 258.23953 | G4: 246.04976 | H4: catalog identifier | I4: 14 And | J4: 5.1848606 | K4: 4.720334
A5: 14 Her | B5: 2 | C5: matched_outside_radius | D5: 79009 | E5: Gl 614 | F5: 57.310894 | G5: 58.48734 | H5: catalog identifier | I5: 14 Her | J5: 5.2017763 | K5: 2.0527442
A6: 16 Cyg B | B6: 1 | C6: unmatched_other | G6: 68.94848 | H6: unassigned | I6: 16 Cyg B | M6: Position candidates require review; component identity is preserved.
A7: 17 Sco | B7: 1 | C7: matched_outside_radius | D7: 79300 | E7: 17Chi Sco | F7: 378.37173 | G7: 407.54218 | H7: catalog identifier | I7: 17 Sco | J7: 0.16843132 | K7: 7.7094681
A8: 18 Del | B8: 1 | C8: matched_outside_radius | D8: 103195 | E8: Musica | F8: 245.59967 | G8: 248.60291 | H8: catalog identifier | I8: 18 Del | J8: 0.96523765 | K8: 1.2228225
A9: 1RXS J160929.1-210524 | B9: 1 | C9: unmatched_other | G9: 453.79768 | H9: unassigned | I9: 1RXS J160929.1-210524 | M9: Position candidates require review; component identity is preserved.
A10: 24 Boo | B10: 1 | C10: matched_outside_radius | D10: 70568 | E10: 24 Boo | F10: 326.15638 | G10: 313.06544 | H10: catalog identifier | I10: 24 Boo | J10: 5.6898553 | K10: 4.0137
A11: 24 Sex | B11: 2 | C11: matched_outside_radius | D11: 50742 | E11: HIP 50887 | F11: 252.63845 | G11: 235.05797 | H11: catalog identifier | I11: 24 Sex | J11: 1.1427504 | K11: 6.9587512
A12: 2MASS J01033563-5515561 A | B12: 1 | C12: unmatched_other | H12: unassigned | I12: 2MASS J01033563-5515561 A | M12: Position candidates require review; component identity is preserved.
A13: 2MASS J01225093-2439505 | B13: 1 | C13: unmatched_other | G13: 110.33251 | H13: unassigned | I13: 2MASS J01225093-2439505 | M13: Position candidates require review; component identity is preserved.
A14: 2MASS J02192210-3925225 | B14: 1 | C14: unmatched_other | H14: unassigned | I14: 2MASS J02192210-3925225 | M14: Position candidates require review; component identity is preserved.
A15: 2MASS J0249-0557 A | B15: 1 | C15: unmatched_other | G15: 215.46314 | H15: unassigned | I15: 2MASS J0249-0557 A | M15: Position candidates require review; component identity is preserved.
A16: 2MASS J03590986+2009361 | B16: 1 | C16: unmatched_other | G16: 383.02174 | H16: unassigned | I16: 2MASS J03590986+2009361 | M16: Position candidates require review; component identity is preserved.
A17: 2MASS J04372171+2651014 | B17: 1 | C17: unmatched_other | G17: 419.05876 | H17: unassigned | I17: 2MASS J04372171+2651014 | M17: Position candidates require review; component identity is preserved.
A18: 2MASS J04414489+2301513 | B18: 1 | C18: unmatched_other | H18: unassigned | I18: 2MASS J04414489+2301513 | M18: Position candidates require review; component identity is preserved.
A19: 2MASS J11011926-7732383 | B19: 1 | C19: unmatched_other | H19: unassigned | I19: 2MASS J11011926-7732383 | M19: Position candidates require review; component identity is preserved.
A20: 2MASS J11550485-7919108 | B20: 1 | C20: unmatched_other | G20: 328.96785 | H20: unassigned | I20: 2MASS J11550485-7919108 | M20: Position candidates require review; component identity is preserved.
A21: 2MASS J12073346-3932539 | B21: 1 | C21: unmatched_other | G21: 209.74464 | H21: unassigned | I21: 2MASS J12073346-3932539 | M21: Position candidates require review; component identity is preserved.
A22: 2MASS J16262785-2625152 | B22: 1 | C22: unmatched_other | G22: 474.34227 | H22: unassigned | I22: 2MASS J16262785-2625152 | M22: Position candidates require review; component identity is preserved.
A23: 2MASS J19383260+4603591 | B23: 3 | C23: unmatched_other | G23: 1292.6621 | H23: unassigned | I23: 2MASS J19383260+4603591 | M23: Position candidates require review; component identity is preserved.
A24: 2MASS J21252752-8138278 | B24: 1 | C24: unmatched_other | G24: 111.26955 | H24: unassigned | I24: 2MASS J21252752-8138278 | M24: Position candidates require review; component identity is preserved.
A25: 2MASS J22362452+4751425 | B25: 1 | C25: unmatched_other | G25: 226.91906 | H25: unassigned | I25: 2MASS J22362452+4751425 | M25: Position candidates require review; component identity is preserved.
A26: 2MASS J22501512+2325342 | B26: 1 | C26: unmatched_other | G26: 186.66223 | H26: unassigned | I26: 2MASS J22501512+2325342 | M26: Position candidates require review; component identity is preserved.
A27: 4 UMa | B27: 1 | C27: matched_outside_radius | D27: 42408 | E27: 4Pi 2UMa | F27: 256.0096 | G27: 239.59545 | H27: catalog identifier | I27: 4 UMa | J27: 1.2992319 | K27: 6.4115353
A28: 47 UMa | B28: 3 | C28: matched_outside_radius | D28: 53565 | E28: Chalawan | F28: 45.866393 | G28: 44.998817 | H28: catalog identifier | I28: 47 UMa | J28: 5.6514797 | K28: 1.8915287
A29: 51 Eri | B29: 1 | C29: matched_outside_radius | D29: 21494 | E29: 51 Eri | F29: 95.984887 | G29: 97.055984 | H29: catalog identifier | I29: 51 Eri | J29: 1.2226568 | K29: 1.1159023
A30: 51 Peg | B30: 1 | C30: matched_outside_radius | D30: 112997 | E30: Helvetios | F30: 50.906161 | G30: 50.428342 | H30: catalog identifier | I30: 51 Peg | J30: 3.4647603 | K30: 0.93862723
A31: 55 Cnc | B31: 5 | C31: matched_outside_radius | D31: 43464 | E31: Copernicus | F31: 40.251285 | G31: 41.048411 | H31: catalog identifier | I31: 55 Cnc | J31: 8.815851 | K31: 1.9803745
A32: 55 Cnc B | B32: 2 | C32: unmatched_other | G32: 40.69551 | H32: unassigned | I32: 55 Cnc B | M32: Position candidates require review; component identity is preserved.
A33: 6 Lyn | B33: 1 | C33: matched_outside_radius | D33: 30966 | E33: 6 Lyn | F33: 182.007 | G33: 178.27675 | H33: catalog identifier | I33: 6 Lyn | J33: 5.28255 | K33: 2.0495094
A34: 61 Vir | B34: 3 | C34: matched_selected | D34: 64720 | E34: Gl 506 | F34: 27.903004 | G34: 27.73412 | H34: catalog identifier | I34: 61 Vir | J34: 23.717508 | K34: 0.60525301
A35: 7 CMa | B35: 2 | C35: matched_outside_radius | D35: 31512 | E35: Gl 239.1 | F35: 64.419472 | G35: 64.611905 | H35: catalog identifier | I35: 7 CMa | J35: 1.4691979 | K35: 0.29871754
A36: 70 Vir | B36: 1 | C36: matched_outside_radius | D36: 65515 | E36: Gl 512.1 | F36: 58.661181 | G36: 58.385579 | H36: catalog identifier | I36: 70 Vir | J36: 9.6687043 | K36: 0.4698203
A37: 75 Cet | B37: 2 | C37: matched_outside_radius | D37: 11763 | E37: 75 Cet | F37: 265.59958 | G37: 270.58357 | H37: catalog identifier | I37: 75 Cet | J37: 0.57225503 | K37: 1.8765074
A38: 8 UMi | B38: 1 | C38: matched_outside_radius | D38: 72910 | E38: Baekdu | F38: 521.8502 | G38: 530.17372 | H38: catalog identifier | I38: 8 UMi | J38: 0.28405134 | K38: 1.595
A39: 81 Cet | B39: 1 | C39: matched_outside_radius | D39: 12215 | E39: 81 Cet | F39: 301.71715 | G39: 330.26595 | H39: catalog identifier | I39: 81 Cet | J39: 0.94409254 | K39: 9.462105
A40: 91 Aqr | B40: 1 | C40: matched_outside_radius | D40: 114493 | E40: Gl 893.2A | F40: 149.81928 | G40: 143.60796 | H40: catalog identifier | I40: 91 Aqr | J40: 5.7576523 | K40: 4.1458763
...

Sheet Measurements
A1: hyg_id | B1: used_in_planets | C1: pl_name | D1: hostname | E1: default_flag | F1: sy_snum | G1: sy_pnum | H1: discoverymethod | I1: disc_year | J1: disc_facility | K1: soltype | L1: pl_controv_flag | M1: pl_refname | N1: pl_orbper | O1: pl_orbpererr1 | P1: pl_orbpererr2 | Q1: pl_orbperlim | R1: pl_orbsmax | S1: pl_orbsmaxerr1 | T1: pl_orbsmaxerr2 | U1: pl_orbsmaxlim | V1: pl_rade | W1: pl_radeerr1 | X1: pl_radeerr2 | Y1: pl_radelim | Z1: pl_radj | AA1: pl_radjerr1 | AB1: pl_radjerr2 | AC1: pl_radjlim | AD1: pl_bmasse | AE1: pl_bmasseerr1 | AF1: pl_bmasseerr2 | AG1: pl_bmasselim | AH1: pl_bmassj | AI1: pl_bmassjerr1 | AJ1: pl_bmassjerr2 | AK1: pl_bmassjlim | AL1: pl_bmassprov | AM1: pl_orbeccen | AN1: pl_orbeccenerr1 | AO1: pl_orbeccenerr2 | AP1: pl_orbeccenlim | AQ1: pl_insol | AR1: pl_insolerr1 | AS1: pl_insolerr2 | AT1: pl_insollim | AU1: pl_eqt | AV1: pl_eqterr1 | AW1: pl_eqterr2 | AX1: pl_eqtlim | AY1: ttv_flag | AZ1: st_refname | BA1: st_spectype | BB1: st_teff | BC1: st_tefferr1 | BD1: st_tefferr2 | BE1: st_tefflim | BF1: st_rad | BG1: st_raderr1 | BH1: st_raderr2 | BI1: st_radlim | BJ1: st_mass | BK1: st_masserr1 | BL1: st_masserr2 | BM1: st_masslim | BN1: st_met | BO1: st_meterr1 | BP1: st_meterr2 | BQ1: st_metlim | BR1: st_metratio | BS1: st_logg | BT1: st_loggerr1 | BU1: st_loggerr2 | BV1: st_logglim | BW1: sy_refname | BX1: rastr | BY1: ra | BZ1: decstr | CA1: dec | CB1: sy_dist | CC1: sy_disterr1 | CD1: sy_disterr2 | CE1: sy_vmag | CF1: sy_vmagerr1 | CG1: sy_vmagerr2 | CH1: sy_kmag | CI1: sy_kmagerr1 | CJ1: sy_kmagerr2 | CK1: sy_gaiamag | CL1: sy_gaiamagerr1 | CM1: sy_gaiamagerr2 | CN1: rowupdate | CO1: pl_pubdate | CP1: releasedate
A2: 64720 | B2: 1 | C2: 61 Vir b | D2: 61 Vir | E2: 1 | F2: 1 | G2: 3 | H2: Radial Velocity | I2: 2009 | J2: Multiple Observatories | K2: Published Confirmed | L2: 0 | M2: <a refstr=VOGT_ET_AL__2010 href=https://ui.adsabs.harvard.edu/abs/2010ApJ...708.1366V/abstract target=ref> Vogt et al. 2010 </a> | N2: 4.215 | O2: 0.0006 | P2: -0.0006 | Q2: 0 | R2: 0.050201 | S2: 5e-06 | T2: -5e-06 | U2: 0 | AD2: 5.1 | AE2: 0.5 | AF2: -0.5 | AG2: 0 | AH2: 0.016 | AI2: 0.002 | AJ2: -0.002 | AK2: 0 | AL2: Msini | AM2: 0.12 | AN2: 0.11 | AO2: -0.11 | AP2: 0 | AY2: 0 | AZ2: <a refstr=VOGT_ET_AL__2010 href=https://ui.adsabs.harvard.edu/abs/2010ApJ...708.1366V/abstract target=ref> Vogt et al. 2010 </a> | BA2: G5 V | BB2: 5577 | BC2: 33 | BD2: -33 | BE2: 0 | BF2: 0.963 | BG2: 0.011 | BH2: -0.011 | BI2: 0 | BJ2: 0.942 | BK2: 0.034 | BL2: -0.029 | BM2: 0 | BN2: -0.01 | BQ2: 0 | BR2: [Fe/H] | BS2: 4.34 | BT2: 0.03 | BU2: -0.03 | BV2: 0 | BW2: <a refstr=STASSUN_ET_AL__2019 href=https://ui.adsabs.harvard.edu/abs/2019AJ....158..138S/abstract target=ref>TICv8</a> | BX2: 13h18m23.15s | BY2: 199.59645 | BZ2: -18d18m56.79s | CA2: -18.315774 | CB2: 8.50332 | CC2: 0.01737 | CD2: -0.0173 | CE2: 4.6955 | CF2: 0.0462 | CG2: -0.0462 | CH2: 2.956 | CI2: 0.236 | CJ2: -0.236 | CK2: 4.54052 | CL2: 0.0055701 | CM2: -0.0055701 | CN2: 2014-05-14 | CO2: 2010-01 | CP2: 2014-05-14
